Workbook

Sheet Zalozenia
A1: Założenia modelu finansowego – wniosek o dofinansowanie z PUP
A2: Żółte komórki z niebieską czcionką = dane do wpisania. Pozostałe komórki liczą się same (formuły). Przykład: fryzjerka mobilna – DANE FIKCYJNE, do podmiany.
A3: Parametr | B3: Wartość | C3: Opis / skąd wziąć | E3: Legenda kolorów
A4: Nazwa / branża | B4: Firma sprzątająca – Kolbuszowa (DANE FIKCYJNE – przykład) | C4: Tylko opis – nie wpływa na obliczenia. | E4: Dane do wpisania
A5: Kwota dotacji z PUP (zł) | B5: 24850 | C5: Kwota, o którą wnioskujesz. Powinna odpowiadać sumie pozycji kosztorysu finansowanych z dotacji. | E5: Formuła w tym arkuszu
A6: Maksymalna kwota dotacji wg ogłoszenia naboru (zł) | B6: 40000 | C6: Z ogłoszenia/regulaminu Twojego PUP (każdy urząd ustala własny limit, ustawowo do 6-krotności przeciętnego wynagrodzenia). | E6: Odwołanie do innego arkusza
A7: Wkład własny – gotówka wniesiona na start (zł) | B7: 8000 | C7: Pieniądze własne przeznaczone na zakupy z kosztorysu (finansowanie: wkład własny) i rezerwę na start.
A8: Data rozpoczęcia działalności | B8: 46447 | C8: Planowana data wpisu do CEIDG (zwykle po podpisaniu umowy z PUP). Miesiąc 1 modelu = miesiąc tej daty.
A9: Forma opodatkowania | B9: ryczałt | C9: skala / liniowy / ryczałt (wybierz z listy).
A10: Stawka ryczałtu (gdy forma = ryczałt) | B10: 0.085 | C10: Np. 8,5% usługi (w tym fryzjerskie), 3% handel, 5,5% roboty budowlane. Sprawdź stawkę dla swojego PKD/PKWiU.
A11: Ulga na start (6 mies. bez składek społecznych) | B11: TAK | C11: TAK / NIE. Tylko gdy w ostatnich 60 mies. nie prowadziłeś działalności i nie zakładasz firmy u byłego pracodawcy.
A12: Liczba miesięcy ulgi na start | B12: 6 | C12: Ustawowo do 6 pełnych miesięcy kalendarzowych (model liczy od miesiąca 1).
A13: Preferencyjne składki ZUS ("mały ZUS") | B13: TAK | C13: TAK / NIE. Podstawa 30% płacy minimalnej przez 24 mies. po uldze na start.
A14: Liczba miesięcy składek preferencyjnych | B14: 24 | C14: Ustawowo 24 miesiące kalendarzowe.
A15: Mały ZUS plus (opcjonalnie, po okresie preferencyjnym) | B15: NIE | C15: TAK / NIE. W pierwszych 12 mies. zwykle niedostępny (wymaga działalności w poprzednim roku i przychodu ≤ 120 000 zł). Działa w modelu tylko w miesiącach po uldze i preferencyjnym ZUS.
A16: Podstawa wymiaru – Mały ZUS plus (zł/mies.) | B16: 3000 | C16: Wpisz podstawę wyliczoną z dochodu za poprzedni rok (50% średniego miesięcznego dochodu). Model ogranicza ją do przedziału 30% płacy min. – 60% prognozowanego wynagrodzenia.
A17: Dobrowolne ubezpieczenie chorobowe | B17: TAK | C17: TAK / NIE. Bez chorobowego nie ma zasiłku chorobowego ani macierzyńskiego z ZUS.
A18: Czynny podatnik VAT | B18: NIE | C18: TAK / NIE. Przy zwolnieniu podmiotowym (limit 240 000 zł w 2026 r., proporcjonalnie w roku startu) wpisz NIE.
A19: Stawka VAT na sprzedaż (gdy czynny VAT) | B19: 0.08 | C19: Np. 8% usługi fryzjerskie, 23% większość usług. Gdy VAT = NIE, ceny w arkuszu Przychody są kwotą przychodu.
A20: Dni robocze w miesiącu | B20: 21 | C20: Ile dni w miesiącu realnie pracujesz.
A21: Godziny pracy z klientem dziennie | B21: 7 | C21: Bez czasu dojazdów i przerw – służy do kontroli obłożenia w arkuszu Przychody.
A22: Spadek przychodów – scenariusz pesymistyczny | B22: 0.3 | C22: Standardowo 30% (wymóg wielu komisji: co jeśli przychody będą niższe).
A25: Kontrole spójności (liczone automatycznie)
A26: Kontrola | B26: Wynik | C26: Co zrobić, gdy wynik nie jest OK
A27: Kwota dotacji ≤ maksymalna kwota z naboru | B27: =IF(Dotacja<=MaxDotacja,"OK","PRZEKROCZONO") -> OK | C27: Zmniejsz kwotę dotacji / kosztorys.
A28: Wydatki z dotacji ≤ kwota dotacji | B28: =IF(KosztorysDotacja<=Dotacja+0.005,"OK","PRZEKROCZONO") -> OK | C28: Przenieś część pozycji na wkład własny albo usuń pozycje.
A29: Kwota dotacji nierozplanowana w kosztorysie (zł) | B29: =Dotacja-KosztorysDotacja -> 0 | C29: Komisja oczekuje, że cała dotacja jest rozpisana na pozycje.
A30: Limity kategorii wg regulaminu | B30: =IF(COUNTIF(Kosztorys!$E$33:$E$37,"PRZEKROCZONY")=0,"OK","PRZEKROCZONY LIMIT") -> OK | C30: Zobacz tabelę limitów w arkuszu Kosztorys.
A31: Najniższe saldo gotówki w 12 mies. – scenariusz bazowy (zł) | B31: =MIN(Prognoza!$K$5:$K$17) -> 2649.5 | C31: Wartość ujemna = brak płynności: zwiększ wkład własny lub obniż koszty.
A32: Najniższe saldo gotówki – scenariusz pesymistyczny (zł) | B32: =MIN(Prognoza!$R$5:$R$17) -> 2649.5 | C32: Ujemne saldo w pesymistycznym scenariuszu opisz w sekcji 09 (plan B).
A33: Najwyższe obłożenie godzin pracy | B33: =MAX(Przychody!$C$38:$N$38) -> 0.86394558 | C33: Powyżej 100% – plan sprzedaży jest fizycznie niewykonalny, popraw liczby.
A34: Przychód vs limit zwolnienia z VAT (rok startu proporcjonalnie, rok następny) | B34: =IF(VATczynny="TAK","czynny VAT",IF(AND(SUMIFS(Koszty!$C$33:$N$33,Koszty!$C$6:$N$6,YEAR(DataStartu))<=LimitVAT*(DATE(YEAR(DataStartu),12,31)-DataStartu+1)/(DATE(YEAR(DataStartu),12,31)-DATE(YEAR(DataStartu),1,1)+1),SUMIFS(Koszty!$C$33:$N$33,Koszty!$C$6:$N$6,YEAR(DataStartu)+1)<=LimitVAT),"OK (poniżej limitu)","UWAGA: możliwe przekroczenie limitu")) -> OK (poniżej limitu) | C34: Limit w roku startu liczony proporcjonalnie do dni działalności; w roku następnym – pełny limit (dla miesięcy objętych modelem).

Sheet Stale-2026
A1: Stałe prawne i parametry na 2026 r.
A2: Weryfikacja: 14.10.2026. Kolumna F: 'zweryfikowano' = potwierdzone w podanym źródle; '[do weryfikacji]' = nie potwierdzono w tej sesji – sprawdź przed użyciem. Od 01.01.2027 kwoty się zmienią (płaca minimalna, podstawy ZUS, od 02.2027 składka zdrowotna).
A4: Parametr | B4: Wartość | C4: Jednostka | D4: Źródło (link) | E4: Akt / data źródła | F4: Status | G4: Uwagi
A5: A. Wynagrodzenia (podstawy do składek)
A6: Minimalne wynagrodzenie 2026 | B6: 4806 | C6: zł/mies. | D6: https://dziennikustaw.gov.pl/D2025000124201.pdf | E6: Rozp. RM z 11.09.2025, Dz.U. 2025 poz. 1242 | F6: zweryfikowano | G6: Tekst rozporządzenia sprawdzony w PDF Dz.U.
A7: Prognozowane przeciętne wynagrodzenie 2026 | B7: 9420 | C7: zł/mies. | D7: https://monitorpolski.gov.pl/M2025000120601.pdf | E7: Obwieszczenie MRPiPS z 19.11.2025, M.P. 2025 poz. 1206 | F7: zweryfikowano | G7: Tekst obwieszczenia sprawdzony w PDF M.P.
A8: Przeciętne wynagrodzenie w sektorze przedsiębiorstw z wypłatami z zysku, IV kw. 2025 | B8: 9228.64 | C8: zł/mies. | D8: https://stat.gov.pl/sygnalne/komunikaty-i-obwieszczenia/lista-komunikatow-i-obwieszczen/obwieszczenie-w-sprawie-przecietnego-miesiecznego-wynagrodzenia-w-sektorze-przedsiebiorstw-wlacznie-z-wyplatami-z-zysku-w-czwartym-kwartale-2025-r-,58,49.html | E8: Obwieszczenie Prezesa GUS z 22.01.2026 | F8: zweryfikowano | G8: Podstawa składki zdrowotnej na ryczałcie od 02.2026 do 01.2027. Potwierdzone też: infakt.pl (22.01.2026).
A9: B. Składki na ubezpieczenia społeczne
A10: Podstawa wymiaru – pełny ZUS (60% prognozowanego wynagrodzenia) | B10: =ROUND(0.6*PrognozaWyn,2) -> 5652 | C10: zł/mies. | D10: https://zielonalinia.gov.pl/stawki-zus-dla-przedsiebiorcow-46392/ | E10: art. 18 ust. 8 ustawy o s.u.s. | F10: zweryfikowano | G10: Wynik: 5 652,00 zł; zielonalinia.gov.pl (stan na 29.05.2026)
A11: Podstawa wymiaru – preferencyjny ZUS (30% płacy minimalnej) | B11: =ROUND(0.3*PlacaMin,2) -> 1441.8 | C11: zł/mies. | D11: https://zielonalinia.gov.pl/stawki-zus-dla-przedsiebiorcow-46392/ | E11: art. 18a ustawy o s.u.s. | F11: zweryfikowano | G11: Wynik: 1 441,80 zł
A12: Stopa składki emerytalnej | B12: 0.1952 | C12: % | D12: https://zielonalinia.gov.pl/stawki-zus-dla-przedsiebiorcow-46392/ | E12: ustawa o s.u.s. | F12: zweryfikowano
A13: Stopa składki rentowej | B13: 0.08 | C13: % | D13: https://zielonalinia.gov.pl/stawki-zus-dla-przedsiebiorcow-46392/ | E13: ustawa o s.u.s. | F13: zweryfikowano
A14: Stopa składki chorobowej (dobrowolna) | B14: 0.0245 | C14: % | D14: https://zielonalinia.gov.pl/stawki-zus-dla-przedsiebiorcow-46392/ | E14: ustawa o s.u.s. | F14: zweryfikowano
A15: Stopa składki wypadkowej (płatnik do 9 ubezpieczonych) | B15: 0.0167 | C15: % | D15: https://poradnikprzedsiebiorcy.pl/-skladka-wypadkowa-jak-ustalic-wlasciwa-stope-procentowa | E15: rok składkowy 04.2026–03.2027 | F15: zweryfikowano | G15: Stopa 50% najwyższej (3,33%). ZUS ustala ją sam dla małych płatników.
A16: Fundusz Pracy + Fundusz Solidarnościowy | B16: 0.0245 | C16: % | D16: https://zielonalinia.gov.pl/stawki-zus-dla-przedsiebiorcow-46392/ | E16: ustawa o promocji zatrudnienia | F16: zweryfikowano | G16: Nie opłaca się, gdy podstawa < minimalne wynagrodzenie (np. preferencyjny ZUS).
A17: Pełny ZUS – składka emerytalna | B17: =ROUND(PodstPelna*StEmer,2) -> 1103.27 | C17: zł/mies. | D17: https://inewi.pl/blog/skladki-zus-dla-przedsiebiorcow-ile-wyniosa | E17: wyliczenie | F17: zweryfikowano | G17: 1 103,27 zł
A18: Pełny ZUS – składka rentowa | B18: =ROUND(PodstPelna*StRent,2) -> 452.16 | C18: zł/mies. | D18: https://inewi.pl/blog/skladki-zus-dla-przedsiebiorcow-ile-wyniosa | E18: wyliczenie | F18: zweryfikowano | G18: 452,16 zł
A19: Pełny ZUS – składka chorobowa | B19: =ROUND(PodstPelna*StChor,2) -> 138.47 | C19: zł/mies. | D19: https://inewi.pl/blog/skladki-zus-dla-przedsiebiorcow-ile-wyniosa | E19: wyliczenie | F19: zweryfikowano | G19: 138,47 zł
A20: Pełny ZUS – składka wypadkowa | B20: =ROUND(PodstPelna*StWyp,2) -> 94.39 | C20: zł/mies. | D20: https://inewi.pl/blog/skladki-zus-dla-przedsiebiorcow-ile-wyniosa | E20: wyliczenie | F20: zweryfikowano | G20: 94,39 zł
A21: Pełny ZUS – FP + FS | B21: =ROUND(PodstPelna*StFP,2) -> 138.47 | C21: zł/mies. | D21: https://inewi.pl/blog/skladki-zus-dla-przedsiebiorcow-ile-wyniosa | E21: wyliczenie | F21: zweryfikowano | G21: 138,47 zł
A22: Pełny ZUS – razem społeczne z chorobowym i FP | B22: =ZUSPelnyEmer+ZUSPelnyRent+ZUSPelnyChor+ZUSPelnyWyp+ZUSPelnyFP -> 1926.76 | C22: zł/mies. | D22: https://inewi.pl/blog/skladki-zus-dla-przedsiebiorcow-ile-wyniosa | E22: wyliczenie | F22: zweryfikowano | G22: 1 926,76 zł (bez chorobowego 1 788,29 zł)
A23: Preferencyjny ZUS – razem społeczne z chorobowym | B23: =ROUND(PodstPref*StEmer,2)+ROUND(PodstPref*StRent,2)+ROUND(PodstPref*StChor,2)+ROUND(PodstPref*StWyp,2) -> 456.18 | C23: zł/mies. | D23: https://inewi.pl/blog/skladki-zus-dla-przedsiebiorcow-ile-wyniosa | E23: wyliczenie | F23: zweryfikowano | G23: 456,18 zł (bez chorobowego 420,86 zł); bez FP
A24: C. Składka zdrowotna (rok składkowy 02.2026–01.2027)
A25: Składka zdrowotna – skala podatkowa (% dochodu) | B25: 0.09 | C25: % | D25: https://www.infakt.pl/blog/?p=81462 | E25: ustawa o świadczeniach opieki zdrowotnej | F25: zweryfikowano | G25: Brak odliczenia od podatku na skali.
A26: Składka zdrowotna – podatek liniowy (% dochodu) | B26: 0.049 | C26: % | D26: https://inewi.pl/blog/skladki-zus-dla-przedsiebiorcow-ile-wyniosa | E26: ustawa o świadczeniach opieki zdrowotnej | F26: zweryfikowano
A27: Minimalna podstawa składki zdrowotnej (skala, liniowy) = 100% płacy minimalnej | B27: =PlacaMin -> 4806 | C27: zł/mies. | D27: https://www.infakt.pl/blog/?p=81462 | E27: od 01.02.2026 (w 2025: 75%) | F27: zweryfikowano | G27: Ustawa przedłużająca obniżoną podstawę 75% nie weszła w życie (weto).
A28: Minimalna składka zdrowotna (skala, liniowy) | B28: =ROUND(0.09*ZdrMinPodst,2) -> 432.54 | C28: zł/mies. | D28: https://www.infakt.pl/blog/?p=81462 | E28: wyliczenie | F28: zweryfikowano | G28: 432,54 zł. Za styczeń 2026 obowiązywały jeszcze kwoty z 2025 r.
A29: Roczny limit odliczenia składki zdrowotnej – liniowy | B29: 14100 | C29: zł/rok | D29: https://www.infakt.pl/blog/?p=81462 | E29: 2026 | F29: zweryfikowano | G29: Potwierdzone w 2 źródłach wtórnych (infakt, zestawienia 2026); brak tekstu obwieszczenia MF w tej sesji.
A30: Ryczałt – próg przychodu rocznego 1 | B30: 60000 | C30: zł/rok | D30: https://www.infakt.pl/blog/?p=81462 | E30: ustawa o świad. opieki zdr. | F30: zweryfikowano
A31: Ryczałt – próg przychodu rocznego 2 | B31: 300000 | C31: zł/rok | D31: https://www.infakt.pl/blog/?p=81462 | E31: ustawa o świad. opieki zdr. | F31: zweryfikowano
A32: Ryczałt – składka zdrowotna przy przychodzie ≤ 60 000 zł (9% × 60% WynIVkw) | B32: =ROUND(0.09*0.6*WynIVkw,2) -> 498.35 | C32: zł/mies. | D32: https://inewi.pl/blog/skladki-zus-dla-przedsiebiorcow-ile-wyniosa | E32: wyliczenie | F32: zweryfikowano | G32: 498,35 zł
A33: Ryczałt – składka zdrowotna przy przychodzie 60 000–300 000 zł (9% × 100%) | B33: =ROUND(0.09*WynIVkw,2) -> 830.58 | C33: zł/mies. | D33: https://inewi.pl/blog/skladki-zus-dla-przedsiebiorcow-ile-wyniosa | E33: wyliczenie | F33: zweryfikowano | G33: 830,58 zł
A34: Ryczałt – składka zdrowotna przy przychodzie > 300 000 zł (9% × 180%) | B34: =ROUND(0.09*1.8*WynIVkw,2) -> 1495.04 | C34: zł/mies. | D34: https://inewi.pl/blog/skladki-zus-dla-przedsiebiorcow-ile-wyniosa | E34: wyliczenie | F34: zweryfikowano | G34: 1 495,04 zł
A35: Ryczałt – część zapłaconej składki zdrowotnej odliczana od przychodu | B35: 0.5 | C35: % | D35: https://sum.money/pl/zus-jdg-ulga-na-start/ | E35: ustawa o ryczałcie | F35: zweryfikowano | G35: Źródło wtórne (zasady Polskiego Ładu, bez zmian w 2026).
A36: D. Podatek dochodowy
A37: Kwota wolna od podatku (skala) | B37: 30000 | C37: zł/rok | D37: https://poradnikprzedsiebiorcy.pl/-skala-podatkowa-nowy-prog-podatkowy-i-kwota-wolna | E37: ustawa o PIT, art. 27 | F37: zweryfikowano
A38: Próg podatkowy (skala) | B38: 120000 | C38: zł/rok | D38: https://poradnikprzedsiebiorcy.pl/-skala-podatkowa-nowy-prog-podatkowy-i-kwota-wolna | E38: ustawa o PIT, art. 27 | F38: zweryfikowano
A39: Stawka podatku – I próg skali | B39: 0.12 | C39: % | D39: https://poradnikprzedsiebiorcy.pl/-skala-podatkowa-nowy-prog-podatkowy-i-kwota-wolna | E39: ustawa o PIT, art. 27 | F39: zweryfikowano
A40: Stawka podatku – II próg skali | B40: 0.32 | C40: % | D40: https://poradnikprzedsiebiorcy.pl/-skala-podatkowa-nowy-prog-podatkowy-i-kwota-wolna | E40: ustawa o PIT, art. 27 | F40: zweryfikowano
A41: Kwota zmniejszająca podatek (12% × kwota wolna) | B41: =KwotaWolna*Stawka1 -> 3600 | C41: zł/rok | D41: https://poradnikprzedsiebiorcy.pl/-skala-podatkowa-nowy-prog-podatkowy-i-kwota-wolna | E41: wyliczenie | F41: zweryfikowano | G41: 3 600 zł
...

Sheet Kosztorys
A1: Kosztorys zakupów (specyfikacja wydatków)
A2: Wpisuj pozycje w wierszach 5–24 (żółte). Kwota do rozliczenia: netto u czynnego podatnika VAT, brutto u zwolnionego z VAT. Linki do ofert – wklej prawdziwe oferty (urząd często ich żąda).
A4: Lp. | B4: Nazwa pozycji | C4: Kategoria | D4: Nowy / używany | E4: Ilość | F4: Cena jedn. netto (zł) | G4: Wartość netto (zł) | H4: Stawka VAT | I4: Kwota VAT (zł) | J4: Wartość brutto (zł) | K4: Kwota do rozliczenia (zł) | L4: Źródło oferty (link) | M4: Finansowanie | N4: Limit kategorii wg regulaminu % | O4: Przekroczenie limitu?
A5: 1 | B5: Odkurzacz piorący Kärcher Puzzi 10/1 | C5: sprzęt | D5: nowy | E5: 1 | F5: 3900 | G5: =E5*F5 -> 3900 | H5: 0.23 | I5: =ROUND(G5*H5,2) -> 897 | J5: =G5+I5 -> 4797 | K5: =IF(VATczynny="TAK",G5,J5) -> 4797 | L5: https://www.ceneo.pl/;szukaj-karcher+puzzi+10/1 | M5: dotacja | N5: =IF(C5="","",IFERROR(VLOOKUP(C5,$A$33:$B$37,2,FALSE()),"brak kategorii")) -> 1 | O5: =IF(C5="","",IFERROR(VLOOKUP(C5,$A$33:$E$37,5,FALSE()),"brak kategorii")) -> OK
A6: 2 | B6: Odkurzacz plecakowy Kärcher BV 5/1 Bp (schody, klatki) | C6: sprzęt | D6: nowy | E6: 1 | F6: 1550 | G6: =E6*F6 -> 1550 | H6: 0.23 | I6: =ROUND(G6*H6,2) -> 356.5 | J6: =G6+I6 -> 1906.5 | K6: =IF(VATczynny="TAK",G6,J6) -> 1906.5 | L6: https://www.ceneo.pl/;szukaj-karcher+bv+5/1 | M6: dotacja | N6: =IF(C6="","",IFERROR(VLOOKUP(C6,$A$33:$B$37,2,FALSE()),"brak kategorii")) -> 1 | O6: =IF(C6="","",IFERROR(VLOOKUP(C6,$A$33:$E$37,5,FALSE()),"brak kategorii")) -> OK
A7: 3 | B7: Odkurzacz na sucho Kärcher T 10/1 Adv HEPA | C7: sprzęt | D7: nowy | E7: 1 | F7: 1100 | G7: =E7*F7 -> 1100 | H7: 0.23 | I7: =ROUND(G7*H7,2) -> 253 | J7: =G7+I7 -> 1353 | K7: =IF(VATczynny="TAK",G7,J7) -> 1353 | L7: https://www.ceneo.pl/;szukaj-karcher+t+10/1+adv | M7: dotacja | N7: =IF(C7="","",IFERROR(VLOOKUP(C7,$A$33:$B$37,2,FALSE()),"brak kategorii")) -> 1 | O7: =IF(C7="","",IFERROR(VLOOKUP(C7,$A$33:$E$37,5,FALSE()),"brak kategorii")) -> OK
A8: 4 | B8: Szorowarka kompaktowa Kärcher BR 30/4 C | C8: sprzęt | D8: nowy | E8: 1 | F8: 6900 | G8: =E8*F8 -> 6900 | H8: 0.23 | I8: =ROUND(G8*H8,2) -> 1587 | J8: =G8+I8 -> 8487 | K8: =IF(VATczynny="TAK",G8,J8) -> 8487 | L8: https://www.ceneo.pl/;szukaj-karcher+br+30/4+c | M8: dotacja | N8: =IF(C8="","",IFERROR(VLOOKUP(C8,$A$33:$B$37,2,FALSE()),"brak kategorii")) -> 1 | O8: =IF(C8="","",IFERROR(VLOOKUP(C8,$A$33:$E$37,5,FALSE()),"brak kategorii")) -> OK
A9: 5 | B9: Myjka do okien Kärcher WV 6 Plus | C9: sprzęt | D9: nowy | E9: 1 | F9: 400 | G9: =E9*F9 -> 400 | H9: 0.23 | I9: =ROUND(G9*H9,2) -> 92 | J9: =G9+I9 -> 492 | K9: =IF(VATczynny="TAK",G9,J9) -> 492 | L9: https://www.ceneo.pl/;szukaj-karcher+wv+6+plus | M9: dotacja | N9: =IF(C9="","",IFERROR(VLOOKUP(C9,$A$33:$B$37,2,FALSE()),"brak kategorii")) -> 1 | O9: =IF(C9="","",IFERROR(VLOOKUP(C9,$A$33:$E$37,5,FALSE()),"brak kategorii")) -> OK
A10: 6 | B10: Wózek serwisowy z prasą do mopów i workiem na odpady | C10: sprzęt | D10: nowy | E10: 1 | F10: 1100 | G10: =E10*F10 -> 1100 | H10: 0.23 | I10: =ROUND(G10*H10,2) -> 253 | J10: =G10+I10 -> 1353 | K10: =IF(VATczynny="TAK",G10,J10) -> 1353 | L10: https://www.ceneo.pl/;szukaj-wozek+serwisowy+do+sprzatania+z+prasa | M10: dotacja | N10: =IF(C10="","",IFERROR(VLOOKUP(C10,$A$33:$B$37,2,FALSE()),"brak kategorii")) -> 1 | O10: =IF(C10="","",IFERROR(VLOOKUP(C10,$A$33:$E$37,5,FALSE()),"brak kategorii")) -> OK
A11: 7 | B11: Mopy płaskie i ściereczki z mikrofibry w 4 kolorach (system stref), uchwyty | C11: inne | D11: nowy | E11: 1 | F11: 650 | G11: =E11*F11 -> 650 | H11: 0.23 | I11: =ROUND(G11*H11,2) -> 149.5 | J11: =G11+I11 -> 799.5 | K11: =IF(VATczynny="TAK",G11,J11) -> 799.5 | L11: https://www.ceneo.pl/;szukaj-mop+plaski+mikrofibra+zestaw | M11: dotacja | N11: =IF(C11="","",IFERROR(VLOOKUP(C11,$A$33:$B$37,2,FALSE()),"brak kategorii")) -> 1 | O11: =IF(C11="","",IFERROR(VLOOKUP(C11,$A$33:$E$37,5,FALSE()),"brak kategorii")) -> OK
A12: 8 | B12: Środki czystości – koncentraty z dozownikami (Ecolabel), pierwszy zapas na 3 mies. | C12: towar | D12: nowy | E12: 1 | F12: 1803.25 | G12: =E12*F12 -> 1803.25 | H12: 0.23 | I12: =ROUND(G12*H12,2) -> 414.75 | J12: =G12+I12 -> 2218 | K12: =IF(VATczynny="TAK",G12,J12) -> 2218 | L12: [oferta hurtowni chemii profesjonalnej – do dołączenia] | M12: dotacja | N12: =IF(C12="","",IFERROR(VLOOKUP(C12,$A$33:$B$37,2,FALSE()),"brak kategorii")) -> 0.3 | O12: =IF(C12="","",IFERROR(VLOOKUP(C12,$A$33:$E$37,5,FALSE()),"brak kategorii")) -> OK
A13: 9 | B13: Oklejenie samochodu folią z nazwą i telefonem | C13: reklama | D13: nowy | E13: 1 | F13: 1300 | G13: =E13*F13 -> 1300 | H13: 0.23 | I13: =ROUND(G13*H13,2) -> 299 | J13: =G13+I13 -> 1599 | K13: =IF(VATczynny="TAK",G13,J13) -> 1599 | L13: [oferta firmy reklamowej – do dołączenia] | M13: dotacja | N13: =IF(C13="","",IFERROR(VLOOKUP(C13,$A$33:$B$37,2,FALSE()),"brak kategorii")) -> 1 | O13: =IF(C13="","",IFERROR(VLOOKUP(C13,$A$33:$E$37,5,FALSE()),"brak kategorii")) -> OK
A14: 10 | B14: Strona www – wizytówka z cennikiem i formularzem | C14: reklama | D14: nowy | E14: 1 | F14: 1500 | G14: =E14*F14 -> 1500 | H14: 0.23 | I14: =ROUND(G14*H14,2) -> 345 | J14: =G14+I14 -> 1845 | K14: =IF(VATczynny="TAK",G14,J14) -> 1845 | L14: [oferta wykonawcy – do dołączenia] | M14: dotacja | N14: =IF(C14="","",IFERROR(VLOOKUP(C14,$A$33:$B$37,2,FALSE()),"brak kategorii")) -> 1 | O14: =IF(C14="","",IFERROR(VLOOKUP(C14,$A$33:$E$37,5,FALSE()),"brak kategorii")) -> OK
A15: 11 | B15: Parownica Kärcher SC 5 EasyFix (sprzątanie bez chemii) | C15: sprzęt | D15: nowy | E15: 1 | F15: 1300 | G15: =E15*F15 -> 1300 | H15: 0.23 | I15: =ROUND(G15*H15,2) -> 299 | J15: =G15+I15 -> 1599 | K15: =IF(VATczynny="TAK",G15,J15) -> 1599 | L15: https://www.ceneo.pl/;szukaj-karcher+sc+5+easyfix | M15: wkład własny | N15: =IF(C15="","",IFERROR(VLOOKUP(C15,$A$33:$B$37,2,FALSE()),"brak kategorii")) -> 1 | O15: =IF(C15="","",IFERROR(VLOOKUP(C15,$A$33:$E$37,5,FALSE()),"brak kategorii")) -> OK
A16: 12 | B16: Zestaw do mycia okien Unger (ściągaczki, kij teleskopowy, wiadro) | C16: sprzęt | D16: nowy | E16: 1 | F16: 700 | G16: =E16*F16 -> 700 | H16: 0.23 | I16: =ROUND(G16*H16,2) -> 161 | J16: =G16+I16 -> 861 | K16: =IF(VATczynny="TAK",G16,J16) -> 861 | L16: https://www.ceneo.pl/;szukaj-unger+zestaw+do+mycia+okien | M16: wkład własny | N16: =IF(C16="","",IFERROR(VLOOKUP(C16,$A$33:$B$37,2,FALSE()),"brak kategorii")) -> 1 | O16: =IF(C16="","",IFERROR(VLOOKUP(C16,$A$33:$E$37,5,FALSE()),"brak kategorii")) -> OK
... A20: 16 | B20: Środki czystości – druga część zapasu | C20: towar | D20: nowy | E20: 1 | F20: 1000 | G20: =E20*F20 -> 1000 | H20: 0.23 | I20: =ROUND(G20*H20,2) -> 230 | J20: =G20+I20 -> 1230 | K20: =IF(VATczynny="TAK",G20,J20) -> 1230 | L20: [oferta hurtowni – do dołączenia] | M20: wkład własny | N20: =IF(C20="","",IFERROR(VLOOKUP(C20,$A$33:$B$37,2,FALSE()),"brak kategorii")) -> 0.3 | O20: =IF(C20="","",IFERROR(VLOOKUP(C20,$A$33:$E$37,5,FALSE()),"brak kategorii")) -> OK
A21: 17 | G21: =E21*F21 -> 0 | I21: =ROUND(G21*H21,2) -> 0 | J21: =G21+I21 -> 0 | K21: =IF(VATczynny="TAK",G21,J21) -> 0 | N21: =IF(C21="","",IFERROR(VLOOKUP(C21,$A$33:$B$37,2,FALSE()),"brak kategorii")) | O21: =IF(C21="","",IFERROR(VLOOKUP(C21,$A$33:$E$37,5,FALSE()),"brak kategorii"))
A22: 18 | G22: =E22*F22 -> 0 | I22: =ROUND(G22*H22,2) -> 0 | J22: =G22+I22 -> 0 | K22: =IF(VATczynny="TAK",G22,J22) -> 0 | N22: =IF(C22="","",IFERROR(VLOOKUP(C22,$A$33:$B$37,2,FALSE()),"brak kategorii")) | O22: =IF(C22="","",IFERROR(VLOOKUP(C22,$A$33:$E$37,5,FALSE()),"brak kategorii"))
A23: 19 | G23: =E23*F23 -> 0 | I23: =ROUND(G23*H23,2) -> 0 | J23: =G23+I23 -> 0 | K23: =IF(VATczynny="TAK",G23,J23) -> 0 | N23: =IF(C23="","",IFERROR(VLOOKUP(C23,$A$33:$B$37,2,FALSE()),"brak kategorii")) | O23: =IF(C23="","",IFERROR(VLOOKUP(C23,$A$33:$E$37,5,FALSE()),"brak kategorii"))
A24: 20 | G24: =E24*F24 -> 0 | I24: =ROUND(G24*H24,2) -> 0 | J24: =G24+I24 -> 0 | K24: =IF(VATczynny="TAK",G24,J24) -> 0 | N24: =IF(C24="","",IFERROR(VLOOKUP(C24,$A$33:$B$37,2,FALSE()),"brak kategorii")) | O24: =IF(C24="","",IFERROR(VLOOKUP(C24,$A$33:$E$37,5,FALSE()),"brak kategorii"))
B25: RAZEM | G25: =SUM(G5:G24) -> 24553.25 | I25: =SUM(I5:I24) -> 5647.25 | J25: =SUM(J5:J24) -> 30200.5 | K25: =SUM(K5:K24) -> 30200.5
B26: w tym finansowane z dotacji | G26: =SUMIFS(G5:G24,$M$5:$M$24,"dotacja") -> 20203.25 | I26: =SUMIFS(I5:I24,$M$5:$M$24,"dotacja") -> 4646.75 | J26: =SUMIFS(J5:J24,$M$5:$M$24,"dotacja") -> 24850 | K26: =SUMIFS(K5:K24,$M$5:$M$24,"dotacja") -> 24850
B27: w tym finansowane z wkładu własnego | G27: =SUMIFS(G5:G24,$M$5:$M$24,"wkład własny") -> 4350 | I27: =SUMIFS(I5:I24,$M$5:$M$24,"wkład własny") -> 1000.5 | J27: =SUMIFS(J5:J24,$M$5:$M$24,"wkład własny") -> 5350.5 | K27: =SUMIFS(K5:K24,$M$5:$M$24,"wkład własny") -> 5350.5
B28: Kwota dotacji (z arkusza Zalozenia) | K28: =Dotacja -> 24850
B29: Pozostało do rozplanowania z dotacji (ujemne = przekroczenie) | K29: =K28-K26 -> 0 | L29: =IF(K29<-0.005,"PRZEKROCZONO KWOTĘ DOTACJI",IF(K29>0.005,"Dotacja nie w pełni rozplanowana","OK – dotacja rozplanowana")) -> OK – dotacja rozplanowana
A31: Limity kategorii wg regulaminu PUP (udział w kwocie dotacji)
A32: Kategoria | B32: Limit wg regulaminu % | C32: Suma z dotacji (zł) | D32: Udział w kwocie dotacji | E32: Status
A33: sprzęt | B33: 1 | C33: =SUMIFS($K$5:$K$24,$C$5:$C$24,A33,$M$5:$M$24,"dotacja") -> 18388.5 | D33: =IF(Dotacja>0,C33/Dotacja,0) -> 0.73997988 | E33: =IF(D33>B33+0.00001,"PRZEKROCZONY","OK") -> OK
A34: towar | B34: 0.3 | C34: =SUMIFS($K$5:$K$24,$C$5:$C$24,A34,$M$5:$M$24,"dotacja") -> 2218 | D34: =IF(Dotacja>0,C34/Dotacja,0) -> 0.089255533 | E34: =IF(D34>B34+0.00001,"PRZEKROCZONY","OK") -> OK
A35: reklama | B35: 1 | C35: =SUMIFS($K$5:$K$24,$C$5:$C$24,A35,$M$5:$M$24,"dotacja") -> 3444 | D35: =IF(Dotacja>0,C35/Dotacja,0) -> 0.13859155 | E35: =IF(D35>B35+0.00001,"PRZEKROCZONY","OK") -> OK
A36: remont | B36: 0 | C36: =SUMIFS($K$5:$K$24,$C$5:$C$24,A36,$M$5:$M$24,"dotacja") -> 0 | D36: =IF(Dotacja>0,C36/Dotacja,0) -> 0 | E36: =IF(D36>B36+0.00001,"PRZEKROCZONY","OK") -> OK
A37: inne | B37: 1 | C37: =SUMIFS($K$5:$K$24,$C$5:$C$24,A37,$M$5:$M$24,"dotacja") -> 799.5 | D37: =IF(Dotacja>0,C37/Dotacja,0) -> 0.032173038 | E37: =IF(D37>B37+0.00001,"PRZEKROCZONY","OK") -> OK
A38: Razem | C38: =SUM(C33:C37) -> 24850 | D38: =SUM(D33:D37) -> 1
A39: Kontrola: suma kategorii = suma z dotacji | C39: =IF(ABS(C38-K26)<0.01,"OK","SPRAWDŹ KATEGORIE (puste/nieznane)") -> OK

Sheet Przychody
A1: Prognoza przychodów – 12 miesięcy
A2: Sprzedaż = liczba sprzedaży przy pełnym obłożeniu × współczynnik rozruchu × mnożnik sezonowy (zaokrąglone do całych sztuk). Ceny: kwota płacona przez klienta (u czynnego VAT-owca model odejmuje VAT).
A4: A. Linie usług / produktów (maks. 5)
A5: Nazwa usługi / produktu | B5: Cena dla klienta (zł) | C5: Liczba sprzedaży / mies. (pełne obłożenie) | D5: Czas 1 usługi (h) | E5: Przychód z 1 sprzedaży (zł, netto)
A6: Sprzątanie biura / gabinetu – wizyta ok. 2 h | B6: 100 | C6: 24 | D6: 2 | E6: =IF(VATczynny="TAK",ROUND(B6/(1+StawkaVAT),2),B6) -> 100
A7: Sprzątanie klatki schodowej – wizyta | B7: 90 | C7: 18 | D7: 1.5 | E7: =IF(VATczynny="TAK",ROUND(B7/(1+StawkaVAT),2),B7) -> 90
A8: Mycie okna dwuskrzydłowego | B8: 45 | C8: 30 | D8: 0.4 | E8: =IF(VATczynny="TAK",ROUND(B8/(1+StawkaVAT),2),B8) -> 45
A9: Sprzątanie jednorazowe: mieszkanie lub po remoncie (średnio) | B9: 450 | C9: 3 | D9: 6 | E9: =IF(VATczynny="TAK",ROUND(B9/(1+StawkaVAT),2),B9) -> 450
A10: Pranie wykładziny lub tapicerki (średnio na zlecenie) | B10: 250 | C10: 3 | D10: 2.5 | E10: =IF(VATczynny="TAK",ROUND(B10/(1+StawkaVAT),2),B10) -> 250
A12: B. Sezonowość wg miesiąca kalendarzowego (1,00 = przeciętny miesiąc)
A13: Miesiąc kalendarzowy | C13: sty | D13: lut | E13: mar | F13: kwi | G13: maj | H13: cze | I13: lip | J13: sie | K13: wrz | L13: paź | M13: lis | N13: gru | O13: średnia
A14: Mnożnik sezonowy | C14: 0.85 | D14: 0.85 | E14: 1.1 | F14: 1.2 | G14: 1.05 | H14: 1 | I14: 0.85 | J14: 0.85 | K14: 1 | L14: 1.05 | M14: 1.05 | N14: 1.15 | O14: =AVERAGE(C14:N14) -> 1
A16: C. Prognoza miesięczna
A17: Miesiąc działalności | C17: 1 | D17: =C17+1 -> 2 | E17: =D17+1 -> 3 | F17: =E17+1 -> 4 | G17: =F17+1 -> 5 | H17: =G17+1 -> 6 | I17: =H17+1 -> 7 | J17: =I17+1 -> 8 | K17: =J17+1 -> 9 | ... N17: =M17+1 -> 12 | O17: Razem 12 mies.
A18: Miesiąc kalendarzowy | C18: =EDATE(DataStartu,C17-1) -> 46447 | D18: =EDATE(DataStartu,D17-1) -> 46478 | E18: =EDATE(DataStartu,E17-1) -> 46508 | F18: =EDATE(DataStartu,F17-1) -> 46539 | G18: =EDATE(DataStartu,G17-1) -> 46569 | H18: =EDATE(DataStartu,H17-1) -> 46600 | I18: =EDATE(DataStartu,I17-1) -> 46631 | J18: =EDATE(DataStartu,J17-1) -> 46661 | ... N18: =EDATE(DataStartu,N17-1) -> 46784
A19: Współczynnik rozruchu | C19: 0.5 | D19: 0.7 | E19: 0.85 | F19: 1 | G19: 1 | H19: 1 | I19: 1 | J19: 1 | K19: 1 | L19: 1 | M19: 1 | N19: 1
A20: Mnożnik sezonowy (z tabeli B) | C20: =INDEX($C$14:$N$14,MONTH(C$18)) -> 1.1 | D20: =INDEX($C$14:$N$14,MONTH(D$18)) -> 1.2 | E20: =INDEX($C$14:$N$14,MONTH(E$18)) -> 1.05 | F20: =INDEX($C$14:$N$14,MONTH(F$18)) -> 1 | G20: =INDEX($C$14:$N$14,MONTH(G$18)) -> 0.85 | H20: =INDEX($C$14:$N$14,MONTH(H$18)) -> 0.85 | I20: =INDEX($C$14:$N$14,MONTH(I$18)) -> 1 | J20: =INDEX($C$14:$N$14,MONTH(J$18)) -> 1.05 | ... N20: =INDEX($C$14:$N$14,MONTH(N$18)) -> 0.85
A21: Liczba sprzedaży (szt. / usług)
A22: =A6 -> Sprzątanie biura / gabinetu – wizyta ok. 2 h | C22: =ROUND($C6*C$19*C$20,0) -> 13 | D22: =ROUND($C6*D$19*D$20,0) -> 20 | E22: =ROUND($C6*E$19*E$20,0) -> 21 | F22: =ROUND($C6*F$19*F$20,0) -> 24 | G22: =ROUND($C6*G$19*G$20,0) -> 20 | H22: =ROUND($C6*H$19*H$20,0) -> 20 | I22: =ROUND($C6*I$19*I$20,0) -> 24 | J22: =ROUND($C6*J$19*J$20,0) -> 25 | ... N22: =ROUND($C6*N$19*N$20,0) -> 20 | O22: =SUM(C22:N22) -> 260
A23: =A7 -> Sprzątanie klatki schodowej – wizyta | C23: =ROUND($C7*C$19*C$20,0) -> 10 | D23: =ROUND($C7*D$19*D$20,0) -> 15 | E23: =ROUND($C7*E$19*E$20,0) -> 16 | F23: =ROUND($C7*F$19*F$20,0) -> 18 | G23: =ROUND($C7*G$19*G$20,0) -> 15 | H23: =ROUND($C7*H$19*H$20,0) -> 15 | I23: =ROUND($C7*I$19*I$20,0) -> 18 | J23: =ROUND($C7*J$19*J$20,0) -> 19 | ... N23: =ROUND($C7*N$19*N$20,0) -> 15 | O23: =SUM(C23:N23) -> 196
A24: =A8 -> Mycie okna dwuskrzydłowego | C24: =ROUND($C8*C$19*C$20,0) -> 17 | D24: =ROUND($C8*D$19*D$20,0) -> 25 | E24: =ROUND($C8*E$19*E$20,0) -> 27 | F24: =ROUND($C8*F$19*F$20,0) -> 30 | G24: =ROUND($C8*G$19*G$20,0) -> 26 | H24: =ROUND($C8*H$19*H$20,0) -> 26 | I24: =ROUND($C8*I$19*I$20,0) -> 30 | J24: =ROUND($C8*J$19*J$20,0) -> 32 | ... N24: =ROUND($C8*N$19*N$20,0) -> 26 | O24: =SUM(C24:N24) -> 332
A25: =A9 -> Sprzątanie jednorazowe: mieszkanie lub po remoncie (średnio) | C25: =ROUND($C9*C$19*C$20,0) -> 2 | D25: =ROUND($C9*D$19*D$20,0) -> 3 | E25: =ROUND($C9*E$19*E$20,0) -> 3 | F25: =ROUND($C9*F$19*F$20,0) -> 3 | G25: =ROUND($C9*G$19*G$20,0) -> 3 | H25: =ROUND($C9*H$19*H$20,0) -> 3 | I25: =ROUND($C9*I$19*I$20,0) -> 3 | J25: =ROUND($C9*J$19*J$20,0) -> 3 | ... N25: =ROUND($C9*N$19*N$20,0) -> 3 | O25: =SUM(C25:N25) -> 35
A26: =A10 -> Pranie wykładziny lub tapicerki (średnio na zlecenie) | C26: =ROUND($C10*C$19*C$20,0) -> 2 | D26: =ROUND($C10*D$19*D$20,0) -> 3 | E26: =ROUND($C10*E$19*E$20,0) -> 3 | F26: =ROUND($C10*F$19*F$20,0) -> 3 | G26: =ROUND($C10*G$19*G$20,0) -> 3 | H26: =ROUND($C10*H$19*H$20,0) -> 3 | I26: =ROUND($C10*I$19*I$20,0) -> 3 | J26: =ROUND($C10*J$19*J$20,0) -> 3 | ... N26: =ROUND($C10*N$19*N$20,0) -> 3 | O26: =SUM(C26:N26) -> 35
A27: Przychód netto (zł)
A28: =A6 -> Sprzątanie biura / gabinetu – wizyta ok. 2 h | C28: =C22*$E$6 -> 1300 | D28: =D22*$E$6 -> 2000 | E28: =E22*$E$6 -> 2100 | F28: =F22*$E$6 -> 2400 | G28: =G22*$E$6 -> 2000 | H28: =H22*$E$6 -> 2000 | I28: =I22*$E$6 -> 2400 | J28: =J22*$E$6 -> 2500 | ... N28: =N22*$E$6 -> 2000 | O28: =SUM(C28:N28) -> 26000
A29: =A7 -> Sprzątanie klatki schodowej – wizyta | C29: =C23*$E$7 -> 900 | D29: =D23*$E$7 -> 1350 | E29: =E23*$E$7 -> 1440 | F29: =F23*$E$7 -> 1620 | G29: =G23*$E$7 -> 1350 | H29: =H23*$E$7 -> 1350 | I29: =I23*$E$7 -> 1620 | J29: =J23*$E$7 -> 1710 | ... N29: =N23*$E$7 -> 1350 | O29: =SUM(C29:N29) -> 17640
A30: =A8 -> Mycie okna dwuskrzydłowego | C30: =C24*$E$8 -> 765 | D30: =D24*$E$8 -> 1125 | E30: =E24*$E$8 -> 1215 | F30: =F24*$E$8 -> 1350 | G30: =G24*$E$8 -> 1170 | H30: =H24*$E$8 -> 1170 | I30: =I24*$E$8 -> 1350 | J30: =J24*$E$8 -> 1440 | ... N30: =N24*$E$8 -> 1170 | O30: =SUM(C30:N30) -> 14940
A31: =A9 -> Sprzątanie jednorazowe: mieszkanie lub po remoncie (średnio) | C31: =C25*$E$9 -> 900 | D31: =D25*$E$9 -> 1350 | E31: =E25*$E$9 -> 1350 | F31: =F25*$E$9 -> 1350 | G31: =G25*$E$9 -> 1350 | H31: =H25*$E$9 -> 1350 | I31: =I25*$E$9 -> 1350 | J31: =J25*$E$9 -> 1350 | ... N31: =N25*$E$9 -> 1350 | O31: =SUM(C31:N31) -> 15750
A32: =A10 -> Pranie wykładziny lub tapicerki (średnio na zlecenie) | C32: =C26*$E$10 -> 500 | D32: =D26*$E$10 -> 750 | E32: =E26*$E$10 -> 750 | F32: =F26*$E$10 -> 750 | G32: =G26*$E$10 -> 750 | H32: =H26*$E$10 -> 750 | I32: =I26*$E$10 -> 750 | J32: =J26*$E$10 -> 750 | ... N32: =N26*$E$10 -> 750 | O32: =SUM(C32:N32) -> 8750
A33: PRZYCHÓD RAZEM (zł) | C33: =SUM(C28:C32) -> 4365 | D33: =SUM(D28:D32) -> 6575 | E33: =SUM(E28:E32) -> 6855 | F33: =SUM(F28:F32) -> 7470 | G33: =SUM(G28:G32) -> 6620 | H33: =SUM(H28:H32) -> 6620 | I33: =SUM(I28:I32) -> 7470 | J33: =SUM(J28:J32) -> 7750 | ... N33: =SUM(N28:N32) -> 6620 | O33: =SUM(C33:N33) -> 83080
A34: Liczba sprzedaży razem | C34: =SUM(C22:C26) -> 44 | D34: =SUM(D22:D26) -> 66 | E34: =SUM(E22:E26) -> 70 | F34: =SUM(F22:F26) -> 78 | G34: =SUM(G22:G26) -> 67 | H34: =SUM(H22:H26) -> 67 | I34: =SUM(I22:I26) -> 78 | J34: =SUM(J22:J26) -> 82 | ... N34: =SUM(N22:N26) -> 67 | O34: =SUM(C34:N34) -> 858
A35: D. Kontrola wykonalności (obłożenie czasu pracy)
A36: Godziny pracy z klientami | C36: =SUMPRODUCT($D$6:$D$10,C22:C26) -> 64.8 | D36: =SUMPRODUCT($D$6:$D$10,D22:D26) -> 98 | E36: =SUMPRODUCT($D$6:$D$10,E22:E26) -> 102.3 | F36: =SUMPRODUCT($D$6:$D$10,F22:F26) -> 112.5 | G36: =SUMPRODUCT($D$6:$D$10,G22:G26) -> 98.4 | H36: =SUMPRODUCT($D$6:$D$10,H22:H26) -> 98.4 | I36: =SUMPRODUCT($D$6:$D$10,I22:I26) -> 112.5 | J36: =SUMPRODUCT($D$6:$D$10,J22:J26) -> 116.8 | ... N36: =SUMPRODUCT($D$6:$D$10,N22:N26) -> 98.4 | O36: =SUM(C36:N36) -> 1244.3
A37: Dostępne godziny (dni robocze × godziny) | C37: =DniRobocze*GodzinyDzien -> 147 | D37: =DniRobocze*GodzinyDzien -> 147 | E37: =DniRobocze*GodzinyDzien -> 147 | F37: =DniRobocze*GodzinyDzien -> 147 | G37: =DniRobocze*GodzinyDzien -> 147 | H37: =DniRobocze*GodzinyDzien -> 147 | I37: =DniRobocze*GodzinyDzien -> 147 | J37: =DniRobocze*GodzinyDzien -> 147 | ... N37: =DniRobocze*GodzinyDzien -> 147 | O37: =SUM(C37:N37) -> 1764
A38: Obłożenie | C38: =IF(C37>0,C36/C37,0) -> 0.44081633 | D38: =IF(D37>0,D36/D37,0) -> 0.66666667 | E38: =IF(E37>0,E36/E37,0) -> 0.69591837 | F38: =IF(F37>0,F36/F37,0) -> 0.76530612 | G38: =IF(G37>0,G36/G37,0) -> 0.66938776 | H38: =IF(H37>0,H36/H37,0) -> 0.66938776 | I38: =IF(I37>0,I36/I37,0) -> 0.76530612 | J38: =IF(J37>0,J36/J37,0) -> 0.79455782 | ... O38: =IF(O37>0,O36/O37,0) -> 0.70538549

Sheet Koszty
A1: Koszty, składki ZUS, składka zdrowotna i podatek – 12 miesięcy
A2: Kolumna B: kwota miesięczna (żółte) lub % przychodu. ZUS wg wariantu z arkusza Zalozenia. Podatek liczony narastająco w roku kalendarzowym (zaliczki), kwota wolna i próg skali resetują się 1 stycznia.
A4: Miesiąc działalności | C4: 1 | D4: =C4+1 -> 2 | E4: =D4+1 -> 3 | F4: =E4+1 -> 4 | G4: =F4+1 -> 5 | H4: =G4+1 -> 6 | I4: =H4+1 -> 7 | J4: =I4+1 -> 8 | K4: =J4+1 -> 9 | ... N4: =M4+1 -> 12 | O4: Razem 12 mies.
A5: Miesiąc kalendarzowy | C5: =EDATE(DataStartu,C4-1) -> 46447 | D5: =EDATE(DataStartu,D4-1) -> 46478 | E5: =EDATE(DataStartu,E4-1) -> 46508 | F5: =EDATE(DataStartu,F4-1) -> 46539 | G5: =EDATE(DataStartu,G4-1) -> 46569 | H5: =EDATE(DataStartu,H4-1) -> 46600 | I5: =EDATE(DataStartu,I4-1) -> 46631 | J5: =EDATE(DataStartu,J4-1) -> 46661 | ... N5: =EDATE(DataStartu,N4-1) -> 46784
A6: Rok kalendarzowy (podatkowy) | C6: =YEAR(C5) -> 2027 | D6: =YEAR(D5) -> 2027 | E6: =YEAR(E5) -> 2027 | F6: =YEAR(F5) -> 2027 | G6: =YEAR(G5) -> 2027 | H6: =YEAR(H5) -> 2027 | I6: =YEAR(I5) -> 2027 | J6: =YEAR(J5) -> 2027 | ... N6: =YEAR(N5) -> 2028
A8: A. Koszty stałe (zł/mies.) | B8: Kwota / mies.
A9: Czynsz / najem lokalu (nie dotyczy – sprzęt w garażu własnym) | B9: 0 | C9: =$B9 -> 0 | D9: =$B9 -> 0 | E9: =$B9 -> 0 | F9: =$B9 -> 0 | G9: =$B9 -> 0 | H9: =$B9 -> 0 | I9: =$B9 -> 0 | J9: =$B9 -> 0 | ... N9: =$B9 -> 0 | O9: =SUM(C9:N9) -> 0
A10: Media (nie dotyczy) | B10: 0 | C10: =$B10 -> 0 | D10: =$B10 -> 0 | E10: =$B10 -> 0 | F10: =$B10 -> 0 | G10: =$B10 -> 0 | H10: =$B10 -> 0 | I10: =$B10 -> 0 | J10: =$B10 -> 0 | ... N10: =$B10 -> 0 | O10: =SUM(C10:N10) -> 0
A11: Telefon i internet | B11: 60 | C11: =$B11 -> 60 | D11: =$B11 -> 60 | E11: =$B11 -> 60 | F11: =$B11 -> 60 | G11: =$B11 -> 60 | H11: =$B11 -> 60 | I11: =$B11 -> 60 | J11: =$B11 -> 60 | ... N11: =$B11 -> 60 | O11: =SUM(C11:N11) -> 720
A12: Księgowość (biuro rachunkowe, ryczałt) | B12: 180 | C12: =$B12 -> 180 | D12: =$B12 -> 180 | E12: =$B12 -> 180 | F12: =$B12 -> 180 | G12: =$B12 -> 180 | H12: =$B12 -> 180 | I12: =$B12 -> 180 | J12: =$B12 -> 180 | ... N12: =$B12 -> 180 | O12: =SUM(C12:N12) -> 2160
A13: Ubezpieczenie OC działalności | B13: 60 | C13: =$B13 -> 60 | D13: =$B13 -> 60 | E13: =$B13 -> 60 | F13: =$B13 -> 60 | G13: =$B13 -> 60 | H13: =$B13 -> 60 | I13: =$B13 -> 60 | J13: =$B13 -> 60 | ... N13: =$B13 -> 60 | O13: =SUM(C13:N13) -> 720
A14: Paliwo i eksploatacja auta | B14: 400 | C14: =$B14 -> 400 | D14: =$B14 -> 400 | E14: =$B14 -> 400 | F14: =$B14 -> 400 | G14: =$B14 -> 400 | H14: =$B14 -> 400 | I14: =$B14 -> 400 | J14: =$B14 -> 400 | ... N14: =$B14 -> 400 | O14: =SUM(C14:N14) -> 4800
A15: Reklama bieżąca | B15: 100 | C15: =$B15 -> 100 | D15: =$B15 -> 100 | E15: =$B15 -> 100 | F15: =$B15 -> 100 | G15: =$B15 -> 100 | H15: =$B15 -> 100 | I15: =$B15 -> 100 | J15: =$B15 -> 100 | ... N15: =$B15 -> 100 | O15: =SUM(C15:N15) -> 1200
A16: Inne (worki, rękawice, konto firmowe, drobne naprawy) | B16: 120 | C16: =$B16 -> 120 | D16: =$B16 -> 120 | E16: =$B16 -> 120 | F16: =$B16 -> 120 | G16: =$B16 -> 120 | H16: =$B16 -> 120 | I16: =$B16 -> 120 | J16: =$B16 -> 120 | ... N16: =$B16 -> 120 | O16: =SUM(C16:N16) -> 1440
A17: Koszty stałe razem | C17: =SUM(C9:C16) -> 920 | D17: =SUM(D9:D16) -> 920 | E17: =SUM(E9:E16) -> 920 | F17: =SUM(F9:F16) -> 920 | G17: =SUM(G9:G16) -> 920 | H17: =SUM(H9:H16) -> 920 | I17: =SUM(I9:I16) -> 920 | J17: =SUM(J9:J16) -> 920 | ... N17: =SUM(N9:N16) -> 920 | O17: =SUM(C17:N17) -> 11040
A19: B. Koszty zmienne
A20: Materiały i kosmetyki zużyte w usługach (% przychodu) | B20: 0.07 | C20: → kwoty w blokach scenariuszy poniżej
A22: C. Składki ZUS na ubezpieczenia społeczne (wg wariantu z Zalozen)
A23: Etap ZUS | C23: =IF(AND(UlgaStart="TAK",C$4<=MiesUlgi),"Ulga na start",IF(AND(Preferencyjny="TAK",C$4<=IF(UlgaStart="TAK",MiesUlgi,0)+MiesPref),"Preferencyjny",IF(MalyZUS="TAK","Mały ZUS plus","Pełny"))) -> Ulga na start | D23: =IF(AND(UlgaStart="TAK",D$4<=MiesUlgi),"Ulga na start",IF(AND(Preferencyjny="TAK",D$4<=IF(UlgaStart="TAK",MiesUlgi,0)+MiesPref),"Preferencyjny",IF(MalyZUS="TAK","Mały ZUS plus","Pełny"))) -> Ulga na start | E23: =IF(AND(UlgaStart="TAK",E$4<=MiesUlgi),"Ulga na start",IF(AND(Preferencyjny="TAK",E$4<=IF(UlgaStart="TAK",MiesUlgi,0)+MiesPref),"Preferencyjny",IF(MalyZUS="TAK","Mały ZUS plus","Pełny"))) -> Ulga na start | F23: =IF(AND(UlgaStart="TAK",F$4<=MiesUlgi),"Ulga na start",IF(AND(Preferencyjny="TAK",F$4<=IF(UlgaStart="TAK",MiesUlgi,0)+MiesPref),"Preferencyjny",IF(MalyZUS="TAK","Mały ZUS plus","Pełny"))) -> Ulga na start | G23: =IF(AND(UlgaStart="TAK",G$4<=MiesUlgi),"Ulga na start",IF(AND(Preferencyjny="TAK",G$4<=IF(UlgaStart="TAK",MiesUlgi,0)+MiesPref),"Preferencyjny",IF(MalyZUS="TAK","Mały ZUS plus","Pełny"))) -> Ulga na start | H23: =IF(AND(UlgaStart="TAK",H$4<=MiesUlgi),"Ulga na start",IF(AND(Preferencyjny="TAK",H$4<=IF(UlgaStart="TAK",MiesUlgi,0)+MiesPref),"Preferencyjny",IF(MalyZUS="TAK","Mały ZUS plus","Pełny"))) -> Ulga na start | I23: =IF(AND(UlgaStart="TAK",I$4<=MiesUlgi),"Ulga na start",IF(AND(Preferencyjny="TAK",I$4<=IF(UlgaStart="TAK",MiesUlgi,0)+MiesPref),"Preferencyjny",IF(MalyZUS="TAK","Mały ZUS plus","Pełny"))) -> Preferencyjny | J23: =IF(AND(UlgaStart="TAK",J$4<=MiesUlgi),"Ulga na start",IF(AND(Preferencyjny="TAK",J$4<=IF(UlgaStart="TAK",MiesUlgi,0)+MiesPref),"Preferencyjny",IF(MalyZUS="TAK","Mały ZUS plus","Pełny"))) -> Preferencyjny | ... N23: =IF(AND(UlgaStart="TAK",N$4<=MiesUlgi),"Ulga na start",IF(AND(Preferencyjny="TAK",N$4<=IF(UlgaStart="TAK",MiesUlgi,0)+MiesPref),"Preferencyjny",IF(MalyZUS="TAK","Mały ZUS plus","Pełny"))) -> Preferencyjny
A24: Podstawa wymiaru (zł) | C24: =IF(C23="Ulga na start",0,IF(C23="Preferencyjny",PodstPref,IF(C23="Mały ZUS plus",MIN(MAX(PodstawaMZP,PodstPref),PodstPelna),PodstPelna))) -> 0 | D24: =IF(D23="Ulga na start",0,IF(D23="Preferencyjny",PodstPref,IF(D23="Mały ZUS plus",MIN(MAX(PodstawaMZP,PodstPref),PodstPelna),PodstPelna))) -> 0 | E24: =IF(E23="Ulga na start",0,IF(E23="Preferencyjny",PodstPref,IF(E23="Mały ZUS plus",MIN(MAX(PodstawaMZP,PodstPref),PodstPelna),PodstPelna))) -> 0 | F24: =IF(F23="Ulga na start",0,IF(F23="Preferencyjny",PodstPref,IF(F23="Mały ZUS plus",MIN(MAX(PodstawaMZP,PodstPref),PodstPelna),PodstPelna))) -> 0 | G24: =IF(G23="Ulga na start",0,IF(G23="Preferencyjny",PodstPref,IF(G23="Mały ZUS plus",MIN(MAX(PodstawaMZP,PodstPref),PodstPelna),PodstPelna))) -> 0 | H24: =IF(H23="Ulga na start",0,IF(H23="Preferencyjny",PodstPref,IF(H23="Mały ZUS plus",MIN(MAX(PodstawaMZP,PodstPref),PodstPelna),PodstPelna))) -> 0 | I24: =IF(I23="Ulga na start",0,IF(I23="Preferencyjny",PodstPref,IF(I23="Mały ZUS plus",MIN(MAX(PodstawaMZP,PodstPref),PodstPelna),PodstPelna))) -> 1441.8 | J24: =IF(J23="Ulga na start",0,IF(J23="Preferencyjny",PodstPref,IF(J23="Mały ZUS plus",MIN(MAX(PodstawaMZP,PodstPref),PodstPelna),PodstPelna))) -> 1441.8 | ... N24: =IF(N23="Ulga na start",0,IF(N23="Preferencyjny",PodstPref,IF(N23="Mały ZUS plus",MIN(MAX(PodstawaMZP,PodstPref),PodstPelna),PodstPelna))) -> 1441.8
A25: Emerytalna | C25: =ROUND(C24*StEmer,2) -> 0 | D25: =ROUND(D24*StEmer,2) -> 0 | E25: =ROUND(E24*StEmer,2) -> 0 | F25: =ROUND(F24*StEmer,2) -> 0 | G25: =ROUND(G24*StEmer,2) -> 0 | H25: =ROUND(H24*StEmer,2) -> 0 | I25: =ROUND(I24*StEmer,2) -> 281.44 | J25: =ROUND(J24*StEmer,2) -> 281.44 | ... N25: =ROUND(N24*StEmer,2) -> 281.44 | O25: =SUM(C25:N25) -> 1688.64
A26: Rentowa | C26: =ROUND(C24*StRent,2) -> 0 | D26: =ROUND(D24*StRent,2) -> 0 | E26: =ROUND(E24*StRent,2) -> 0 | F26: =ROUND(F24*StRent,2) -> 0 | G26: =ROUND(G24*StRent,2) -> 0 | H26: =ROUND(H24*StRent,2) -> 0 | I26: =ROUND(I24*StRent,2) -> 115.34 | J26: =ROUND(J24*StRent,2) -> 115.34 | ... N26: =ROUND(N24*StRent,2) -> 115.34 | O26: =SUM(C26:N26) -> 692.04
A27: Chorobowa (dobrowolna) | C27: =IF(Chorobowe="TAK",ROUND(C24*StChor,2),0) -> 0 | D27: =IF(Chorobowe="TAK",ROUND(D24*StChor,2),0) -> 0 | E27: =IF(Chorobowe="TAK",ROUND(E24*StChor,2),0) -> 0 | F27: =IF(Chorobowe="TAK",ROUND(F24*StChor,2),0) -> 0 | G27: =IF(Chorobowe="TAK",ROUND(G24*StChor,2),0) -> 0 | H27: =IF(Chorobowe="TAK",ROUND(H24*StChor,2),0) -> 0 | I27: =IF(Chorobowe="TAK",ROUND(I24*StChor,2),0) -> 35.32 | J27: =IF(Chorobowe="TAK",ROUND(J24*StChor,2),0) -> 35.32 | ... N27: =IF(Chorobowe="TAK",ROUND(N24*StChor,2),0) -> 35.32 | O27: =SUM(C27:N27) -> 211.92
A28: Wypadkowa | C28: =ROUND(C24*StWyp,2) -> 0 | D28: =ROUND(D24*StWyp,2) -> 0 | E28: =ROUND(E24*StWyp,2) -> 0 | F28: =ROUND(F24*StWyp,2) -> 0 | G28: =ROUND(G24*StWyp,2) -> 0 | H28: =ROUND(H24*StWyp,2) -> 0 | I28: =ROUND(I24*StWyp,2) -> 24.08 | J28: =ROUND(J24*StWyp,2) -> 24.08 | ... N28: =ROUND(N24*StWyp,2) -> 24.08 | O28: =SUM(C28:N28) -> 144.48
A29: Fundusz Pracy + FS (gdy podstawa ≥ płaca minimalna) | C29: =IF(C24>=PlacaMin,ROUND(C24*StFP,2),0) -> 0 | D29: =IF(D24>=PlacaMin,ROUND(D24*StFP,2),0) -> 0 | E29: =IF(E24>=PlacaMin,ROUND(E24*StFP,2),0) -> 0 | F29: =IF(F24>=PlacaMin,ROUND(F24*StFP,2),0) -> 0 | G29: =IF(G24>=PlacaMin,ROUND(G24*StFP,2),0) -> 0 | H29: =IF(H24>=PlacaMin,ROUND(H24*StFP,2),0) -> 0 | I29: =IF(I24>=PlacaMin,ROUND(I24*StFP,2),0) -> 0 | J29: =IF(J24>=PlacaMin,ROUND(J24*StFP,2),0) -> 0 | ... N29: =IF(N24>=PlacaMin,ROUND(N24*StFP,2),0) -> 0 | O29: =SUM(C29:N29) -> 0
A30: Składki społeczne razem | C30: =SUM(C25:C29) -> 0 | D30: =SUM(D25:D29) -> 0 | E30: =SUM(E25:E29) -> 0 | F30: =SUM(F25:F29) -> 0 | G30: =SUM(G25:G29) -> 0 | H30: =SUM(H25:H29) -> 0 | I30: =SUM(I25:I29) -> 456.18 | J30: =SUM(J25:J29) -> 456.18 | ... N30: =SUM(N25:N29) -> 456.18 | O30: =SUM(C30:N30) -> 2737.08
A32: D. Scenariusz bazowy
A33: Przychód netto (zł) | C33: =Przychody!C33*(1-0) -> 4365 | D33: =Przychody!D33*(1-0) -> 6575 | E33: =Przychody!E33*(1-0) -> 6855 | F33: =Przychody!F33*(1-0) -> 7470 | G33: =Przychody!G33*(1-0) -> 6620 | H33: =Przychody!H33*(1-0) -> 6620 | I33: =Przychody!I33*(1-0) -> 7470 | J33: =Przychody!J33*(1-0) -> 7750 | ... N33: =Przychody!N33*(1-0) -> 6620 | O33: =SUM(C33:N33) -> 83080
A34: Koszty stałe | C34: =C$17 -> 920 | D34: =D$17 -> 920 | E34: =E$17 -> 920 | F34: =F$17 -> 920 | G34: =G$17 -> 920 | H34: =H$17 -> 920 | I34: =I$17 -> 920 | J34: =J$17 -> 920 | ... N34: =N$17 -> 920 | O34: =SUM(C34:N34) -> 11040
A35: Materiały (koszty zmienne) | C35: =ROUND(C33*MaterialyPct,2) -> 305.55 | D35: =ROUND(D33*MaterialyPct,2) -> 460.25 | E35: =ROUND(E33*MaterialyPct,2) -> 479.85 | F35: =ROUND(F33*MaterialyPct,2) -> 522.9 | G35: =ROUND(G33*MaterialyPct,2) -> 463.4 | H35: =ROUND(H33*MaterialyPct,2) -> 463.4 | I35: =ROUND(I33*MaterialyPct,2) -> 522.9 | J35: =ROUND(J33*MaterialyPct,2) -> 542.5 | ... N35: =ROUND(N33*MaterialyPct,2) -> 463.4 | O35: =SUM(C35:N35) -> 5815.6
A36: Koszty operacyjne razem (bez ZUS i podatku) | C36: =C34+C35 -> 1225.55 | D36: =D34+D35 -> 1380.25 | E36: =E34+E35 -> 1399.85 | F36: =F34+F35 -> 1442.9 | G36: =G34+G35 -> 1383.4 | H36: =H34+H35 -> 1383.4 | I36: =I34+I35 -> 1442.9 | J36: =J34+J35 -> 1462.5 | ... N36: =N34+N35 -> 1383.4 | O36: =SUM(C36:N36) -> 16855.6
A37: Składki społeczne ZUS | C37: =C$30 -> 0 | D37: =D$30 -> 0 | E37: =E$30 -> 0 | F37: =F$30 -> 0 | G37: =G$30 -> 0 | H37: =H$30 -> 0 | I37: =I$30 -> 456.18 | J37: =J$30 -> 456.18 | ... N37: =N$30 -> 456.18 | O37: =SUM(C37:N37) -> 2737.08
A38: Dochód po składkach społecznych (podstawa zdrowotnej skala/liniowy) | C38: =C33-C36-C37 -> 3139.45 | D38: =D33-D36-D37 -> 5194.75 | E38: =E33-E36-E37 -> 5455.15 | F38: =F33-F36-F37 -> 6027.1 | G38: =G33-G36-G37 -> 5236.6 | H38: =H33-H36-H37 -> 5236.6 | I38: =I33-I36-I37 -> 5570.92 | J38: =J33-J36-J37 -> 5831.32 | ... N38: =N33-N36-N37 -> 4780.42 | O38: =SUM(C38:N38) -> 63487.32
A39: Przychód narastająco w roku kalendarzowym (próg ryczałtu) | C39: =SUMIFS($C33:$N33,$C$6:$N$6,C$6,$C$4:$N$4,"<="&C$4) -> 4365 | D39: =SUMIFS($C33:$N33,$C$6:$N$6,D$6,$C$4:$N$4,"<="&D$4) -> 10940 | E39: =SUMIFS($C33:$N33,$C$6:$N$6,E$6,$C$4:$N$4,"<="&E$4) -> 17795 | F39: =SUMIFS($C33:$N33,$C$6:$N$6,F$6,$C$4:$N$4,"<="&F$4) -> 25265 | G39: =SUMIFS($C33:$N33,$C$6:$N$6,G$6,$C$4:$N$4,"<="&G$4) -> 31885 | H39: =SUMIFS($C33:$N33,$C$6:$N$6,H$6,$C$4:$N$4,"<="&H$4) -> 38505 | I39: =SUMIFS($C33:$N33,$C$6:$N$6,I$6,$C$4:$N$4,"<="&I$4) -> 45975 | J39: =SUMIFS($C33:$N33,$C$6:$N$6,J$6,$C$4:$N$4,"<="&J$4) -> 53725 | ... N39: =SUMIFS($C33:$N33,$C$6:$N$6,N$6,$C$4:$N$4,"<="&N$4) -> 13240
A40: Składka zdrowotna | C40: =IF(FormaOpodatkowania="ryczałt",IF(C39<=RyczProg1,ZdrRycz1,IF(C39<=RyczProg2,ZdrRycz2,ZdrRycz3)),MAX(ZdrMin,ROUND(MAX(0,C38)*IF(FormaOpodatkowania="liniowy",ZdrLin,ZdrSkala),2))) -> 498.35 | D40: =IF(FormaOpodatkowania="ryczałt",IF(D39<=RyczProg1,ZdrRycz1,IF(D39<=RyczProg2,ZdrRycz2,ZdrRycz3)),MAX(ZdrMin,ROUND(MAX(0,D38)*IF(FormaOpodatkowania="liniowy",ZdrLin,ZdrSkala),2))) -> 498.35 | E40: =IF(FormaOpodatkowania="ryczałt",IF(E39<=RyczProg1,ZdrRycz1,IF(E39<=RyczProg2,ZdrRycz2,ZdrRycz3)),MAX(ZdrMin,ROUND(MAX(0,E38)*IF(FormaOpodatkowania="liniowy",ZdrLin,ZdrSkala),2))) -> 498.35 | F40: =IF(FormaOpodatkowania="ryczałt",IF(F39<=RyczProg1,ZdrRycz1,IF(F39<=RyczProg2,ZdrRycz2,ZdrRycz3)),MAX(ZdrMin,ROUND(MAX(0,F38)*IF(FormaOpodatkowania="liniowy",ZdrLin,ZdrSkala),2))) -> 498.35 | G40: =IF(FormaOpodatkowania="ryczałt",IF(G39<=RyczProg1,ZdrRycz1,IF(G39<=RyczProg2,ZdrRycz2,ZdrRycz3)),MAX(ZdrMin,ROUND(MAX(0,G38)*IF(FormaOpodatkowania="liniowy",ZdrLin,ZdrSkala),2))) -> 498.35 | H40: =IF(FormaOpodatkowania="ryczałt",IF(H39<=RyczProg1,ZdrRycz1,IF(H39<=RyczProg2,ZdrRycz2,ZdrRycz3)),MAX(ZdrMin,ROUND(MAX(0,H38)*IF(FormaOpodatkowania="liniowy",ZdrLin,ZdrSkala),2))) -> 498.35 | I40: =IF(FormaOpodatkowania="ryczałt",IF(I39<=RyczProg1,ZdrRycz1,IF(I39<=RyczProg2,ZdrRycz2,ZdrRycz3)),MAX(ZdrMin,ROUND(MAX(0,I38)*IF(FormaOpodatkowania="liniowy",ZdrLin,ZdrSkala),2))) -> 498.35 | J40: =IF(FormaOpodatkowania="ryczałt",IF(J39<=RyczProg1,ZdrRycz1,IF(J39<=RyczProg2,ZdrRycz2,ZdrRycz3)),MAX(ZdrMin,ROUND(MAX(0,J38)*IF(FormaOpodatkowania="liniowy",ZdrLin,ZdrSkala),2))) -> 498.35 | ... N40: =IF(FormaOpodatkowania="ryczałt",IF(N39<=RyczProg1,ZdrRycz1,IF(N39<=RyczProg2,ZdrRycz2,ZdrRycz3)),MAX(ZdrMin,ROUND(MAX(0,N38)*IF(FormaOpodatkowania="liniowy",ZdrLin,ZdrSkala),2))) -> 498.35 | O40: =SUM(C40:N40) -> 6644.66
A41: Składka zdrowotna narastająco w roku (pomocniczo) | C41: =SUMIFS($C40:$N40,$C$6:$N$6,C$6,$C$4:$N$4,"<="&C$4) -> 498.35 | D41: =SUMIFS($C40:$N40,$C$6:$N$6,D$6,$C$4:$N$4,"<="&D$4) -> 996.7 | E41: =SUMIFS($C40:$N40,$C$6:$N$6,E$6,$C$4:$N$4,"<="&E$4) -> 1495.05 | F41: =SUMIFS($C40:$N40,$C$6:$N$6,F$6,$C$4:$N$4,"<="&F$4) -> 1993.4 | G41: =SUMIFS($C40:$N40,$C$6:$N$6,G$6,$C$4:$N$4,"<="&G$4) -> 2491.75 | H41: =SUMIFS($C40:$N40,$C$6:$N$6,H$6,$C$4:$N$4,"<="&H$4) -> 2990.1 | I41: =SUMIFS($C40:$N40,$C$6:$N$6,I$6,$C$4:$N$4,"<="&I$4) -> 3488.45 | J41: =SUMIFS($C40:$N40,$C$6:$N$6,J$6,$C$4:$N$4,"<="&J$4) -> 3986.8 | ... N41: =SUMIFS($C40:$N40,$C$6:$N$6,N$6,$C$4:$N$4,"<="&N$4) -> 996.7
A42: Odliczenie składki zdrowotnej (liniowy: do limitu; ryczałt: 50%) | C42: =IF(FormaOpodatkowania="liniowy",MIN(C41,LimitZdrLin)-MIN(C41-C40,LimitZdrLin),IF(FormaOpodatkowania="ryczałt",ROUND(C40*RyczOdlicz,2),0)) -> 249.18 | D42: =IF(FormaOpodatkowania="liniowy",MIN(D41,LimitZdrLin)-MIN(D41-D40,LimitZdrLin),IF(FormaOpodatkowania="ryczałt",ROUND(D40*RyczOdlicz,2),0)) -> 249.18 | E42: =IF(FormaOpodatkowania="liniowy",MIN(E41,LimitZdrLin)-MIN(E41-E40,LimitZdrLin),IF(FormaOpodatkowania="ryczałt",ROUND(E40*RyczOdlicz,2),0)) -> 249.18 | F42: =IF(FormaOpodatkowania="liniowy",MIN(F41,LimitZdrLin)-MIN(F41-F40,LimitZdrLin),IF(FormaOpodatkowania="ryczałt",ROUND(F40*RyczOdlicz,2),0)) -> 249.18 | G42: =IF(FormaOpodatkowania="liniowy",MIN(G41,LimitZdrLin)-MIN(G41-G40,LimitZdrLin),IF(FormaOpodatkowania="ryczałt",ROUND(G40*RyczOdlicz,2),0)) -> 249.18 | H42: =IF(FormaOpodatkowania="liniowy",MIN(H41,LimitZdrLin)-MIN(H41-H40,LimitZdrLin),IF(FormaOpodatkowania="ryczałt",ROUND(H40*RyczOdlicz,2),0)) -> 249.18 | I42: =IF(FormaOpodatkowania="liniowy",MIN(I41,LimitZdrLin)-MIN(I41-I40,LimitZdrLin),IF(FormaOpodatkowania="ryczałt",ROUND(I40*RyczOdlicz,2),0)) -> 249.18 | J42: =IF(FormaOpodatkowania="liniowy",MIN(J41,LimitZdrLin)-MIN(J41-J40,LimitZdrLin),IF(FormaOpodatkowania="ryczałt",ROUND(J40*RyczOdlicz,2),0)) -> 249.18 | ... N42: =IF(FormaOpodatkowania="liniowy",MIN(N41,LimitZdrLin)-MIN(N41-N40,LimitZdrLin),IF(FormaOpodatkowania="ryczałt",ROUND(N40*RyczOdlicz,2),0)) -> 249.18 | O42: =SUM(C42:N42) -> 3322.38
A43: Podstawa opodatkowania w miesiącu | C43: =IF(FormaOpodatkowania="ryczałt",C33-C37-C42,C33-C36-C37-C42) -> 4115.82 | D43: =IF(FormaOpodatkowania="ryczałt",D33-D37-D42,D33-D36-D37-D42) -> 6325.82 | E43: =IF(FormaOpodatkowania="ryczałt",E33-E37-E42,E33-E36-E37-E42) -> 6605.82 | F43: =IF(FormaOpodatkowania="ryczałt",F33-F37-F42,F33-F36-F37-F42) -> 7220.82 | G43: =IF(FormaOpodatkowania="ryczałt",G33-G37-G42,G33-G36-G37-G42) -> 6370.82 | H43: =IF(FormaOpodatkowania="ryczałt",H33-H37-H42,H33-H36-H37-H42) -> 6370.82 | I43: =IF(FormaOpodatkowania="ryczałt",I33-I37-I42,I33-I36-I37-I42) -> 6764.64 | J43: =IF(FormaOpodatkowania="ryczałt",J33-J37-J42,J33-J36-J37-J42) -> 7044.64 | ... N43: =IF(FormaOpodatkowania="ryczałt",N33-N37-N42,N33-N36-N37-N42) -> 5914.64 | O43: =SUM(C43:N43) -> 77020.54
A44: Podstawa narastająco w roku | C44: =SUMIFS($C43:$N43,$C$6:$N$6,C$6,$C$4:$N$4,"<="&C$4) -> 4115.82 | D44: =SUMIFS($C43:$N43,$C$6:$N$6,D$6,$C$4:$N$4,"<="&D$4) -> 10441.64 | E44: =SUMIFS($C43:$N43,$C$6:$N$6,E$6,$C$4:$N$4,"<="&E$4) -> 17047.46 | F44: =SUMIFS($C43:$N43,$C$6:$N$6,F$6,$C$4:$N$4,"<="&F$4) -> 24268.28 | G44: =SUMIFS($C43:$N43,$C$6:$N$6,G$6,$C$4:$N$4,"<="&G$4) -> 30639.1 | H44: =SUMIFS($C43:$N43,$C$6:$N$6,H$6,$C$4:$N$4,"<="&H$4) -> 37009.92 | I44: =SUMIFS($C43:$N43,$C$6:$N$6,I$6,$C$4:$N$4,"<="&I$4) -> 43774.56 | J44: =SUMIFS($C43:$N43,$C$6:$N$6,J$6,$C$4:$N$4,"<="&J$4) -> 50819.2 | ... N44: =SUMIFS($C43:$N43,$C$6:$N$6,N$6,$C$4:$N$4,"<="&N$4) -> 11829.28
A45: Podatek należny narastająco w roku | C45: =ROUND(IF(FormaOpodatkowania="ryczałt",MAX(0,C44)*StawkaRyczaltu,IF(FormaOpodatkowania="liniowy",MAX(0,C44)*StLiniowy,IF(C44<=ProgPod,MAX(0,C44*Stawka1-KwotaZmn),ProgPod*Stawka1-KwotaZmn+(C44-ProgPod)*Stawka2))),0) -> 350 | D45: =ROUND(IF(FormaOpodatkowania="ryczałt",MAX(0,D44)*StawkaRyczaltu,IF(FormaOpodatkowania="liniowy",MAX(0,D44)*StLiniowy,IF(D44<=ProgPod,MAX(0,D44*Stawka1-KwotaZmn),ProgPod*Stawka1-KwotaZmn+(D44-ProgPod)*Stawka2))),0) -> 888 | E45: =ROUND(IF(FormaOpodatkowania="ryczałt",MAX(0,E44)*StawkaRyczaltu,IF(FormaOpodatkowania="liniowy",MAX(0,E44)*StLiniowy,IF(E44<=ProgPod,MAX(0,E44*Stawka1-KwotaZmn),ProgPod*Stawka1-KwotaZmn+(E44-ProgPod)*Stawka2))),0) -> 1449 | F45: =ROUND(IF(FormaOpodatkowania="ryczałt",MAX(0,F44)*StawkaRyczaltu,IF(FormaOpodatkowania="liniowy",MAX(0,F44)*StLiniowy,IF(F44<=ProgPod,MAX(0,F44*Stawka1-KwotaZmn),ProgPod*Stawka1-KwotaZmn+(F44-ProgPod)*Stawka2))),0) -> 2063 | G45: =ROUND(IF(FormaOpodatkowania="ryczałt",MAX(0,G44)*StawkaRyczaltu,IF(FormaOpodatkowania="liniowy",MAX(0,G44)*StLiniowy,IF(G44<=ProgPod,MAX(0,G44*Stawka1-KwotaZmn),ProgPod*Stawka1-KwotaZmn+(G44-ProgPod)*Stawka2))),0) -> 2604 | H45: =ROUND(IF(FormaOpodatkowania="ryczałt",MAX(0,H44)*StawkaRyczaltu,IF(FormaOpodatkowania="liniowy",MAX(0,H44)*StLiniowy,IF(H44<=ProgPod,MAX(0,H44*Stawka1-KwotaZmn),ProgPod*Stawka1-KwotaZmn+(H44-ProgPod)*Stawka2))),0) -> 3146 | I45: =ROUND(IF(FormaOpodatkowania="ryczałt",MAX(0,I44)*StawkaRyczaltu,IF(FormaOpodatkowania="liniowy",MAX(0,I44)*StLiniowy,IF(I44<=ProgPod,MAX(0,I44*Stawka1-KwotaZmn),ProgPod*Stawka1-KwotaZmn+(I44-ProgPod)*Stawka2))),0) -> 3721 | J45: =ROUND(IF(FormaOpodatkowania="ryczałt",MAX(0,J44)*StawkaRyczaltu,IF(FormaOpodatkowania="liniowy",MAX(0,J44)*StLiniowy,IF(J44<=ProgPod,MAX(0,J44*Stawka1-KwotaZmn),ProgPod*Stawka1-KwotaZmn+(J44-ProgPod)*Stawka2))),0) -> 4320 | ... N45: =ROUND(IF(FormaOpodatkowania="ryczałt",MAX(0,N44)*StawkaRyczaltu,IF(FormaOpodatkowania="liniowy",MAX(0,N44)*StLiniowy,IF(N44<=ProgPod,MAX(0,N44*Stawka1-KwotaZmn),ProgPod*Stawka1-KwotaZmn+(N44-ProgPod)*Stawka2))),0) -> 1005
...

Sheet Prognoza
A1: Rachunek wyników i przepływy pieniężne – 12 miesięcy
A2: Miesiąc 0 = start: wpływ dotacji i wkładu własnego, zapłata za zakupy z kosztorysu. Scenariusz pesymistyczny w kolumnach M–R.
C3: SCENARIUSZ BAZOWY | M3: ="SCENARIUSZ PESYMISTYCZNY (przychody −"&TEXT(SpadekPesym,"0%")&")" -> SCENARIUSZ PESYMISTYCZNY (przychody −30%)
A4: Miesiąc | B4: Data | C4: Przychody (zł) | D4: Koszty operacyjne (zł) | E4: Składki społeczne ZUS (zł) | F4: Składka zdrowotna (zł) | G4: Koszty razem (zł) | H4: Wynik przed opodatkowaniem (zł) | I4: Podatek dochodowy (zł) | J4: Wynik netto (zł) | K4: Gotówka skumulowana (zł) | M4: Przychody (zł) | N4: Koszty razem (zł) | O4: Wynik przed opodatkowaniem (zł) | P4: Podatek dochodowy (zł) | Q4: Wynik netto (zł) | R4: Gotówka skumulowana (zł) | S4: Miesiąc z zyskiem (1/0)
A5: 0 | B5: =DataStartu -> 46447 | C5: Start: dotacja + wkład własny − zakupy z kosztorysu | K5: =Dotacja+WkladWlasny-KosztorysRazem -> 2649.5 | R5: =Dotacja+WkladWlasny-KosztorysRazem -> 2649.5
A6: 1 | B6: =EDATE(DataStartu,$A6-1) -> 46447 | C6: =INDEX(Koszty!$C$33:$N$33,$A6) -> 4365 | D6: =INDEX(Koszty!$C$36:$N$36,$A6) -> 1225.55 | E6: =INDEX(Koszty!$C$37:$N$37,$A6) -> 0 | F6: =INDEX(Koszty!$C$40:$N$40,$A6) -> 498.35 | G6: =D6+E6+F6 -> 1723.9 | H6: =C6-G6 -> 2641.1 | I6: =INDEX(Koszty!$C$47:$N$47,$A6) -> 350 | J6: =H6-I6 -> 2291.1 | K6: =K5+J6 -> 4940.6 | M6: =INDEX(Koszty!$C$53:$N$53,$A6) -> 3055.5 | N6: =INDEX(Koszty!$C$68:$N$68,$A6) -> 1632.24 | O6: =M6-N6 -> 1423.26 | P6: =INDEX(Koszty!$C$67:$N$67,$A6) -> 239 | Q6: =O6-P6 -> 1184.26 | R6: =R5+Q6 -> 3833.76 | S6: =IF(J6>0,1,0) -> 1
A7: 2 | B7: =EDATE(DataStartu,$A7-1) -> 46478 | C7: =INDEX(Koszty!$C$33:$N$33,$A7) -> 6575 | D7: =INDEX(Koszty!$C$36:$N$36,$A7) -> 1380.25 | E7: =INDEX(Koszty!$C$37:$N$37,$A7) -> 0 | F7: =INDEX(Koszty!$C$40:$N$40,$A7) -> 498.35 | G7: =D7+E7+F7 -> 1878.6 | H7: =C7-G7 -> 4696.4 | I7: =INDEX(Koszty!$C$47:$N$47,$A7) -> 538 | J7: =H7-I7 -> 4158.4 | K7: =K6+J7 -> 9099 | M7: =INDEX(Koszty!$C$53:$N$53,$A7) -> 4602.5 | N7: =INDEX(Koszty!$C$68:$N$68,$A7) -> 1740.53 | O7: =M7-N7 -> 2861.97 | P7: =INDEX(Koszty!$C$67:$N$67,$A7) -> 370 | Q7: =O7-P7 -> 2491.97 | R7: =R6+Q7 -> 6325.73 | S7: =IF(J7>0,1,0) -> 1
A8: 3 | B8: =EDATE(DataStartu,$A8-1) -> 46508 | C8: =INDEX(Koszty!$C$33:$N$33,$A8) -> 6855 | D8: =INDEX(Koszty!$C$36:$N$36,$A8) -> 1399.85 | E8: =INDEX(Koszty!$C$37:$N$37,$A8) -> 0 | F8: =INDEX(Koszty!$C$40:$N$40,$A8) -> 498.35 | G8: =D8+E8+F8 -> 1898.2 | H8: =C8-G8 -> 4956.8 | I8: =INDEX(Koszty!$C$47:$N$47,$A8) -> 561 | J8: =H8-I8 -> 4395.8 | K8: =K7+J8 -> 13494.8 | M8: =INDEX(Koszty!$C$53:$N$53,$A8) -> 4798.5 | N8: =INDEX(Koszty!$C$68:$N$68,$A8) -> 1754.25 | O8: =M8-N8 -> 3044.25 | P8: =INDEX(Koszty!$C$67:$N$67,$A8) -> 386 | Q8: =O8-P8 -> 2658.25 | R8: =R7+Q8 -> 8983.98 | S8: =IF(J8>0,1,0) -> 1
A9: 4 | B9: =EDATE(DataStartu,$A9-1) -> 46539 | C9: =INDEX(Koszty!$C$33:$N$33,$A9) -> 7470 | D9: =INDEX(Koszty!$C$36:$N$36,$A9) -> 1442.9 | E9: =INDEX(Koszty!$C$37:$N$37,$A9) -> 0 | F9: =INDEX(Koszty!$C$40:$N$40,$A9) -> 498.35 | G9: =D9+E9+F9 -> 1941.25 | H9: =C9-G9 -> 5528.75 | I9: =INDEX(Koszty!$C$47:$N$47,$A9) -> 614 | J9: =H9-I9 -> 4914.75 | K9: =K8+J9 -> 18409.55 | M9: =INDEX(Koszty!$C$53:$N$53,$A9) -> 5229 | N9: =INDEX(Koszty!$C$68:$N$68,$A9) -> 1784.38 | O9: =M9-N9 -> 3444.62 | P9: =INDEX(Koszty!$C$67:$N$67,$A9) -> 424 | Q9: =O9-P9 -> 3020.62 | R9: =R8+Q9 -> 12004.6 | S9: =IF(J9>0,1,0) -> 1
A10: 5 | B10: =EDATE(DataStartu,$A10-1) -> 46569 | C10: =INDEX(Koszty!$C$33:$N$33,$A10) -> 6620 | D10: =INDEX(Koszty!$C$36:$N$36,$A10) -> 1383.4 | E10: =INDEX(Koszty!$C$37:$N$37,$A10) -> 0 | F10: =INDEX(Koszty!$C$40:$N$40,$A10) -> 498.35 | G10: =D10+E10+F10 -> 1881.75 | H10: =C10-G10 -> 4738.25 | I10: =INDEX(Koszty!$C$47:$N$47,$A10) -> 541 | J10: =H10-I10 -> 4197.25 | K10: =K9+J10 -> 22606.8 | M10: =INDEX(Koszty!$C$53:$N$53,$A10) -> 4634 | N10: =INDEX(Koszty!$C$68:$N$68,$A10) -> 1742.73 | O10: =M10-N10 -> 2891.27 | P10: =INDEX(Koszty!$C$67:$N$67,$A10) -> 372 | Q10: =O10-P10 -> 2519.27 | R10: =R9+Q10 -> 14523.87 | S10: =IF(J10>0,1,0) -> 1
A11: 6 | B11: =EDATE(DataStartu,$A11-1) -> 46600 | C11: =INDEX(Koszty!$C$33:$N$33,$A11) -> 6620 | D11: =INDEX(Koszty!$C$36:$N$36,$A11) -> 1383.4 | E11: =INDEX(Koszty!$C$37:$N$37,$A11) -> 0 | F11: =INDEX(Koszty!$C$40:$N$40,$A11) -> 498.35 | G11: =D11+E11+F11 -> 1881.75 | H11: =C11-G11 -> 4738.25 | I11: =INDEX(Koszty!$C$47:$N$47,$A11) -> 542 | J11: =H11-I11 -> 4196.25 | K11: =K10+J11 -> 26803.05 | M11: =INDEX(Koszty!$C$53:$N$53,$A11) -> 4634 | N11: =INDEX(Koszty!$C$68:$N$68,$A11) -> 1742.73 | O11: =M11-N11 -> 2891.27 | P11: =INDEX(Koszty!$C$67:$N$67,$A11) -> 373 | Q11: =O11-P11 -> 2518.27 | R11: =R10+Q11 -> 17042.14 | S11: =IF(J11>0,1,0) -> 1
A12: 7 | B12: =EDATE(DataStartu,$A12-1) -> 46631 | C12: =INDEX(Koszty!$C$33:$N$33,$A12) -> 7470 | D12: =INDEX(Koszty!$C$36:$N$36,$A12) -> 1442.9 | E12: =INDEX(Koszty!$C$37:$N$37,$A12) -> 456.18 | F12: =INDEX(Koszty!$C$40:$N$40,$A12) -> 498.35 | G12: =D12+E12+F12 -> 2397.43 | H12: =C12-G12 -> 5072.57 | I12: =INDEX(Koszty!$C$47:$N$47,$A12) -> 575 | J12: =H12-I12 -> 4497.57 | K12: =K11+J12 -> 31300.62 | M12: =INDEX(Koszty!$C$53:$N$53,$A12) -> 5229 | N12: =INDEX(Koszty!$C$68:$N$68,$A12) -> 2240.56 | O12: =M12-N12 -> 2988.44 | P12: =INDEX(Koszty!$C$67:$N$67,$A12) -> 384 | Q12: =O12-P12 -> 2604.44 | R12: =R11+Q12 -> 19646.58 | S12: =IF(J12>0,1,0) -> 1
A13: 8 | B13: =EDATE(DataStartu,$A13-1) -> 46661 | C13: =INDEX(Koszty!$C$33:$N$33,$A13) -> 7750 | D13: =INDEX(Koszty!$C$36:$N$36,$A13) -> 1462.5 | E13: =INDEX(Koszty!$C$37:$N$37,$A13) -> 456.18 | F13: =INDEX(Koszty!$C$40:$N$40,$A13) -> 498.35 | G13: =D13+E13+F13 -> 2417.03 | H13: =C13-G13 -> 5332.97 | I13: =INDEX(Koszty!$C$47:$N$47,$A13) -> 599 | J13: =H13-I13 -> 4733.97 | K13: =K12+J13 -> 36034.59 | M13: =INDEX(Koszty!$C$53:$N$53,$A13) -> 5425 | N13: =INDEX(Koszty!$C$68:$N$68,$A13) -> 2254.28 | O13: =M13-N13 -> 3170.72 | P13: =INDEX(Koszty!$C$67:$N$67,$A13) -> 402 | Q13: =O13-P13 -> 2768.72 | R13: =R12+Q13 -> 22415.3 | S13: =IF(J13>0,1,0) -> 1
A14: 9 | B14: =EDATE(DataStartu,$A14-1) -> 46692 | C14: =INDEX(Koszty!$C$33:$N$33,$A14) -> 7750 | D14: =INDEX(Koszty!$C$36:$N$36,$A14) -> 1462.5 | E14: =INDEX(Koszty!$C$37:$N$37,$A14) -> 456.18 | F14: =INDEX(Koszty!$C$40:$N$40,$A14) -> 830.58 | G14: =D14+E14+F14 -> 2749.26 | H14: =C14-G14 -> 5000.74 | I14: =INDEX(Koszty!$C$47:$N$47,$A14) -> 584 | J14: =H14-I14 -> 4416.74 | K14: =K13+J14 -> 40451.33 | M14: =INDEX(Koszty!$C$53:$N$53,$A14) -> 5425 | N14: =INDEX(Koszty!$C$68:$N$68,$A14) -> 2254.28 | O14: =M14-N14 -> 3170.72 | P14: =INDEX(Koszty!$C$67:$N$67,$A14) -> 401 | Q14: =O14-P14 -> 2769.72 | R14: =R13+Q14 -> 25185.02 | S14: =IF(J14>0,1,0) -> 1
